Workbook

Sheet Diário_Avaliações
A1: Data | B1: Mês | C1: Dia da Semana | D1: Qtd. | E1: Meta | F1: % do Mês | G1: Faltam | H1: Matric. | I1: Novo | J1: H | K1: M | L1: Lucas | M1: Edy | N1: Eduardo | O1: Luiz | P1: Maria | Q1: (livre) | R1: (livre) | S1: (livre) | T1: Conferência | U1: Observação
A2: 46054 | B2: =IF($A2="","",CHOOSE(MONTH($A2),"Janeiro","Fevereiro","Março","Abril","Maio","Junho","Julho","Agosto","Setembro","Outubro","Novembro","Dezembro")) | C2: =IF($A2="","",CHOOSE(WEEKDAY($A2),"Domingo","Segunda-feira","Terça-feira","Quarta-feira","Quinta-feira","Sexta-feira","Sábado")) | E2: =IFERROR(INDEX(Consolidado_Mensal!$B$2:$B$12,MATCH($B2,Consolidado_Mensal!$A$2:$A$12,0)),"") | F2: =IF($E2="","",SUMIFS($D$2:$D2,$B$2:$B2,$B2)/$E2) | G2: =IF($E2="","",MAX(0,$E2-SUMIFS($D$2:$D2,$B$2:$B2,$B2))) | T2: =IF($D2="","",IF(AND($D2=0,SUM($H2:$S2)=0),"OK",IF(SUM($H2:$S2)=0,"Sem detalhe",IF(AND(OR(SUM($H2:$I2)=$D2,SUM($H2:$I2)=0),OR(SUM($J2:$K2)=$D2,SUM($J2:$K2)=0),OR(SUM($L2:$S2)=$D2,SUM($L2:$S2)=0)),"OK","Verificar: "&IF(AND(SUM($H2:$I2)<>$D2,SUM($H2:$I2)<>0),"perfil ","")&IF(AND(SUM($J2:$K2)<>$D2,SUM($J2:$K2)<>0),"gênero ","")&IF(AND(SUM($L2:$S2)<>$D2,SUM($L2:$S2)<>0),"professor","")))))
A3: 46055 | B3: =IF($A3="","",CHOOSE(MONTH($A3),"Janeiro","Fevereiro","Março","Abril","Maio","Junho","Julho","Agosto","Setembro","Outubro","Novembro","Dezembro")) | C3: =IF($A3="","",CHOOSE(WEEKDAY($A3),"Domingo","Segunda-feira","Terça-feira","Quarta-feira","Quinta-feira","Sexta-feira","Sábado")) | E3: =IFERROR(INDEX(Consolidado_Mensal!$B$2:$B$12,MATCH($B3,Consolidado_Mensal!$A$2:$A$12,0)),"") | F3: =IF($E3="","",SUMIFS($D$2:$D3,$B$2:$B3,$B3)/$E3) | G3: =IF($E3="","",MAX(0,$E3-SUMIFS($D$2:$D3,$B$2:$B3,$B3))) | T3: =IF($D3="","",IF(AND($D3=0,SUM($H3:$S3)=0),"OK",IF(SUM($H3:$S3)=0,"Sem detalhe",IF(AND(OR(SUM($H3:$I3)=$D3,SUM($H3:$I3)=0),OR(SUM($J3:$K3)=$D3,SUM($J3:$K3)=0),OR(SUM($L3:$S3)=$D3,SUM($L3:$S3)=0)),"OK","Verificar: "&IF(AND(SUM($H3:$I3)<>$D3,SUM($H3:$I3)<>0),"perfil ","")&IF(AND(SUM($J3:$K3)<>$D3,SUM($J3:$K3)<>0),"gênero ","")&IF(AND(SUM($L3:$S3)<>$D3,SUM($L3:$S3)<>0),"professor","")))))
A4: 46056 | B4: =IF($A4="","",CHOOSE(MONTH($A4),"Janeiro","Fevereiro","Março","Abril","Maio","Junho","Julho","Agosto","Setembro","Outubro","Novembro","Dezembro")) | C4: =IF($A4="","",CHOOSE(WEEKDAY($A4),"Domingo","Segunda-feira","Terça-feira","Quarta-feira","Quinta-feira","Sexta-feira","Sábado")) | E4: =IFERROR(INDEX(Consolidado_Mensal!$B$2:$B$12,MATCH($B4,Consolidado_Mensal!$A$2:$A$12,0)),"") | F4: =IF($E4="","",SUMIFS($D$2:$D4,$B$2:$B4,$B4)/$E4) | G4: =IF($E4="","",MAX(0,$E4-SUMIFS($D$2:$D4,$B$2:$B4,$B4))) | T4: =IF($D4="","",IF(AND($D4=0,SUM($H4:$S4)=0),"OK",IF(SUM($H4:$S4)=0,"Sem detalhe",IF(AND(OR(SUM($H4:$I4)=$D4,SUM($H4:$I4)=0),OR(SUM($J4:$K4)=$D4,SUM($J4:$K4)=0),OR(SUM($L4:$S4)=$D4,SUM($L4:$S4)=0)),"OK","Verificar: "&IF(AND(SUM($H4:$I4)<>$D4,SUM($H4:$I4)<>0),"perfil ","")&IF(AND(SUM($J4:$K4)<>$D4,SUM($J4:$K4)<>0),"gênero ","")&IF(AND(SUM($L4:$S4)<>$D4,SUM($L4:$S4)<>0),"professor","")))))
A5: 46057 | B5: =IF($A5="","",CHOOSE(MONTH($A5),"Janeiro","Fevereiro","Março","Abril","Maio","Junho","Julho","Agosto","Setembro","Outubro","Novembro","Dezembro")) | C5: =IF($A5="","",CHOOSE(WEEKDAY($A5),"Domingo","Segunda-feira","Terça-feira","Quarta-feira","Quinta-feira","Sexta-feira","Sábado")) | E5: =IFERROR(INDEX(Consolidado_Mensal!$B$2:$B$12,MATCH($B5,Consolidado_Mensal!$A$2:$A$12,0)),"") | F5: =IF($E5="","",SUMIFS($D$2:$D5,$B$2:$B5,$B5)/$E5) | G5: =IF($E5="","",MAX(0,$E5-SUMIFS($D$2:$D5,$B$2:$B5,$B5))) | T5: =IF($D5="","",IF(AND($D5=0,SUM($H5:$S5)=0),"OK",IF(SUM($H5:$S5)=0,"Sem detalhe",IF(AND(OR(SUM($H5:$I5)=$D5,SUM($H5:$I5)=0),OR(SUM($J5:$K5)=$D5,SUM($J5:$K5)=0),OR(SUM($L5:$S5)=$D5,SUM($L5:$S5)=0)),"OK","Verificar: "&IF(AND(SUM($H5:$I5)<>$D5,SUM($H5:$I5)<>0),"perfil ","")&IF(AND(SUM($J5:$K5)<>$D5,SUM($J5:$K5)<>0),"gênero ","")&IF(AND(SUM($L5:$S5)<>$D5,SUM($L5:$S5)<>0),"professor","")))))
A6: 46058 | B6: =IF($A6="","",CHOOSE(MONTH($A6),"Janeiro","Fevereiro","Março","Abril","Maio","Junho","Julho","Agosto","Setembro","Outubro","Novembro","Dezembro")) | C6: =IF($A6="","",CHOOSE(WEEKDAY($A6),"Domingo","Segunda-feira","Terça-feira","Quarta-feira","Quinta-feira","Sexta-feira","Sábado")) | E6: =IFERROR(INDEX(Consolidado_Mensal!$B$2:$B$12,MATCH($B6,Consolidado_Mensal!$A$2:$A$12,0)),"") | F6: =IF($E6="","",SUMIFS($D$2:$D6,$B$2:$B6,$B6)/$E6) | G6: =IF($E6="","",MAX(0,$E6-SUMIFS($D$2:$D6,$B$2:$B6,$B6))) | T6: =IF($D6="","",IF(AND($D6=0,SUM($H6:$S6)=0),"OK",IF(SUM($H6:$S6)=0,"Sem detalhe",IF(AND(OR(SUM($H6:$I6)=$D6,SUM($H6:$I6)=0),OR(SUM($J6:$K6)=$D6,SUM($J6:$K6)=0),OR(SUM($L6:$S6)=$D6,SUM($L6:$S6)=0)),"OK","Verificar: "&IF(AND(SUM($H6:$I6)<>$D6,SUM($H6:$I6)<>0),"perfil ","")&IF(AND(SUM($J6:$K6)<>$D6,SUM($J6:$K6)<>0),"gênero ","")&IF(AND(SUM($L6:$S6)<>$D6,SUM($L6:$S6)<>0),"professor","")))))
A7: 46059 | B7: =IF($A7="","",CHOOSE(MONTH($A7),"Janeiro","Fevereiro","Março","Abril","Maio","Junho","Julho","Agosto","Setembro","Outubro","Novembro","Dezembro")) | C7: =IF($A7="","",CHOOSE(WEEKDAY($A7),"Domingo","Segunda-feira","Terça-feira","Quarta-feira","Quinta-feira","Sexta-feira","Sábado")) | E7: =IFERROR(INDEX(Consolidado_Mensal!$B$2:$B$12,MATCH($B7,Consolidado_Mensal!$A$2:$A$12,0)),"") | F7: =IF($E7="","",SUMIFS($D$2:$D7,$B$2:$B7,$B7)/$E7) | G7: =IF($E7="","",MAX(0,$E7-SUMIFS($D$2:$D7,$B$2:$B7,$B7))) | T7: =IF($D7="","",IF(AND($D7=0,SUM($H7:$S7)=0),"OK",IF(SUM($H7:$S7)=0,"Sem detalhe",IF(AND(OR(SUM($H7:$I7)=$D7,SUM($H7:$I7)=0),OR(SUM($J7:$K7)=$D7,SUM($J7:$K7)=0),OR(SUM($L7:$S7)=$D7,SUM($L7:$S7)=0)),"OK","Verificar: "&IF(AND(SUM($H7:$I7)<>$D7,SUM($H7:$I7)<>0),"perfil ","")&IF(AND(SUM($J7:$K7)<>$D7,SUM($J7:$K7)<>0),"gênero ","")&IF(AND(SUM($L7:$S7)<>$D7,SUM($L7:$S7)<>0),"professor","")))))
A8: 46060 | B8: =IF($A8="","",CHOOSE(MONTH($A8),"Janeiro","Fevereiro","Março","Abril","Maio","Junho","Julho","Agosto","Setembro","Outubro","Novembro","Dezembro")) | C8: =IF($A8="","",CHOOSE(WEEKDAY($A8),"Domingo","Segunda-feira","Terça-feira","Quarta-feira","Quinta-feira","Sexta-feira","Sábado")) | E8: =IFERROR(INDEX(Consolidado_Mensal!$B$2:$B$12,MATCH($B8,Consolidado_Mensal!$A$2:$A$12,0)),"") | F8: =IF($E8="","",SUMIFS($D$2:$D8,$B$2:$B8,$B8)/$E8) | G8: =IF($E8="","",MAX(0,$E8-SUMIFS($D$2:$D8,$B$2:$B8,$B8))) | T8: =IF($D8="","",IF(AND($D8=0,SUM($H8:$S8)=0),"OK",IF(SUM($H8:$S8)=0,"Sem detalhe",IF(AND(OR(SUM($H8:$I8)=$D8,SUM($H8:$I8)=0),OR(SUM($J8:$K8)=$D8,SUM($J8:$K8)=0),OR(SUM($L8:$S8)=$D8,SUM($L8:$S8)=0)),"OK","Verificar: "&IF(AND(SUM($H8:$I8)<>$D8,SUM($H8:$I8)<>0),"perfil ","")&IF(AND(SUM($J8:$K8)<>$D8,SUM($J8:$K8)<>0),"gênero ","")&IF(AND(SUM($L8:$S8)<>$D8,SUM($L8:$S8)<>0),"professor","")))))
A9: 46061 | B9: =IF($A9="","",CHOOSE(MONTH($A9),"Janeiro","Fevereiro","Março","Abril","Maio","Junho","Julho","Agosto","Setembro","Outubro","Novembro","Dezembro")) | C9: =IF($A9="","",CHOOSE(WEEKDAY($A9),"Domingo","Segunda-feira","Terça-feira","Quarta-feira","Quinta-feira","Sexta-feira","Sábado")) | E9: =IFERROR(INDEX(Consolidado_Mensal!$B$2:$B$12,MATCH($B9,Consolidado_Mensal!$A$2:$A$12,0)),"") | F9: =IF($E9="","",SUMIFS($D$2:$D9,$B$2:$B9,$B9)/$E9) | G9: =IF($E9="","",MAX(0,$E9-SUMIFS($D$2:$D9,$B$2:$B9,$B9))) | T9: =IF($D9="","",IF(AND($D9=0,SUM($H9:$S9)=0),"OK",IF(SUM($H9:$S9)=0,"Sem detalhe",IF(AND(OR(SUM($H9:$I9)=$D9,SUM($H9:$I9)=0),OR(SUM($J9:$K9)=$D9,SUM($J9:$K9)=0),OR(SUM($L9:$S9)=$D9,SUM($L9:$S9)=0)),"OK","Verificar: "&IF(AND(SUM($H9:$I9)<>$D9,SUM($H9:$I9)<>0),"perfil ","")&IF(AND(SUM($J9:$K9)<>$D9,SUM($J9:$K9)<>0),"gênero ","")&IF(AND(SUM($L9:$S9)<>$D9,SUM($L9:$S9)<>0),"professor","")))))
A10: 46062 | B10: =IF($A10="","",CHOOSE(MONTH($A10),"Janeiro","Fevereiro","Março","Abril","Maio","Junho","Julho","Agosto","Setembro","Outubro","Novembro","Dezembro")) | C10: =IF($A10="","",CHOOSE(WEEKDAY($A10),"Domingo","Segunda-feira","Terça-feira","Quarta-feira","Quinta-feira","Sexta-feira","Sábado")) | E10: =IFERROR(INDEX(Consolidado_Mensal!$B$2:$B$12,MATCH($B10,Consolidado_Mensal!$A$2:$A$12,0)),"") | F10: =IF($E10="","",SUMIFS($D$2:$D10,$B$2:$B10,$B10)/$E10) | G10: =IF($E10="","",MAX(0,$E10-SUMIFS($D$2:$D10,$B$2:$B10,$B10))) | T10: =IF($D10="","",IF(AND($D10=0,SUM($H10:$S10)=0),"OK",IF(SUM($H10:$S10)=0,"Sem detalhe",IF(AND(OR(SUM($H10:$I10)=$D10,SUM($H10:$I10)=0),OR(SUM($J10:$K10)=$D10,SUM($J10:$K10)=0),OR(SUM($L10:$S10)=$D10,SUM($L10:$S10)=0)),"OK","Verificar: "&IF(AND(SUM($H10:$I10)<>$D10,SUM($H10:$I10)<>0),"perfil ","")&IF(AND(SUM($J10:$K10)<>$D10,SUM($J10:$K10)<>0),"gênero ","")&IF(AND(SUM($L10:$S10)<>$D10,SUM($L10:$S10)<>0),"professor","")))))
A11: 46063 | B11: =IF($A11="","",CHOOSE(MONTH($A11),"Janeiro","Fevereiro","Março","Abril","Maio","Junho","Julho","Agosto","Setembro","Outubro","Novembro","Dezembro")) | C11: =IF($A11="","",CHOOSE(WEEKDAY($A11),"Domingo","Segunda-feira","Terça-feira","Quarta-feira","Quinta-feira","Sexta-feira","Sábado")) | E11: =IFERROR(INDEX(Consolidado_Mensal!$B$2:$B$12,MATCH($B11,Consolidado_Mensal!$A$2:$A$12,0)),"") | F11: =IF($E11="","",SUMIFS($D$2:$D11,$B$2:$B11,$B11)/$E11) | G11: =IF($E11="","",MAX(0,$E11-SUMIFS($D$2:$D11,$B$2:$B11,$B11))) | T11: =IF($D11="","",IF(AND($D11=0,SUM($H11:$S11)=0),"OK",IF(SUM($H11:$S11)=0,"Sem detalhe",IF(AND(OR(SUM($H11:$I11)=$D11,SUM($H11:$I11)=0),OR(SUM($J11:$K11)=$D11,SUM($J11:$K11)=0),OR(SUM($L11:$S11)=$D11,SUM($L11:$S11)=0)),"OK","Verificar: "&IF(AND(SUM($H11:$I11)<>$D11,SUM($H11:$I11)<>0),"perfil ","")&IF(AND(SUM($J11:$K11)<>$D11,SUM($J11:$K11)<>0),"gênero ","")&IF(AND(SUM($L11:$S11)<>$D11,SUM($L11:$S11)<>0),"professor","")))))
A12: 46064 | B12: =IF($A12="","",CHOOSE(MONTH($A12),"Janeiro","Fevereiro","Março","Abril","Maio","Junho","Julho","Agosto","Setembro","Outubro","Novembro","Dezembro")) | C12: =IF($A12="","",CHOOSE(WEEKDAY($A12),"Domingo","Segunda-feira","Terça-feira","Quarta-feira","Quinta-feira","Sexta-feira","Sábado")) | E12: =IFERROR(INDEX(Consolidado_Mensal!$B$2:$B$12,MATCH($B12,Consolidado_Mensal!$A$2:$A$12,0)),"") | F12: =IF($E12="","",SUMIFS($D$2:$D12,$B$2:$B12,$B12)/$E12) | G12: =IF($E12="","",MAX(0,$E12-SUMIFS($D$2:$D12,$B$2:$B12,$B12))) | T12: =IF($D12="","",IF(AND($D12=0,SUM($H12:$S12)=0),"OK",IF(SUM($H12:$S12)=0,"Sem detalhe",IF(AND(OR(SUM($H12:$I12)=$D12,SUM($H12:$I12)=0),OR(SUM($J12:$K12)=$D12,SUM($J12:$K12)=0),OR(SUM($L12:$S12)=$D12,SUM($L12:$S12)=0)),"OK","Verificar: "&IF(AND(SUM($H12:$I12)<>$D12,SUM($H12:$I12)<>0),"perfil ","")&IF(AND(SUM($J12:$K12)<>$D12,SUM($J12:$K12)<>0),"gênero ","")&IF(AND(SUM($L12:$S12)<>$D12,SUM($L12:$S12)<>0),"professor","")))))
A13: 46065 | B13: =IF($A13="","",CHOOSE(MONTH($A13),"Janeiro","Fevereiro","Março","Abril","Maio","Junho","Julho","Agosto","Setembro","Outubro","Novembro","Dezembro")) | C13: =IF($A13="","",CHOOSE(WEEKDAY($A13),"Domingo","Segunda-feira","Terça-feira","Quarta-feira","Quinta-feira","Sexta-feira","Sábado")) | E13: =IFERROR(INDEX(Consolidado_Mensal!$B$2:$B$12,MATCH($B13,Consolidado_Mensal!$A$2:$A$12,0)),"") | F13: =IF($E13="","",SUMIFS($D$2:$D13,$B$2:$B13,$B13)/$E13) | G13: =IF($E13="","",MAX(0,$E13-SUMIFS($D$2:$D13,$B$2:$B13,$B13))) | T13: =IF($D13="","",IF(AND($D13=0,SUM($H13:$S13)=0),"OK",IF(SUM($H13:$S13)=0,"Sem detalhe",IF(AND(OR(SUM($H13:$I13)=$D13,SUM($H13:$I13)=0),OR(SUM($J13:$K13)=$D13,SUM($J13:$K13)=0),OR(SUM($L13:$S13)=$D13,SUM($L13:$S13)=0)),"OK","Verificar: "&IF(AND(SUM($H13:$I13)<>$D13,SUM($H13:$I13)<>0),"perfil ","")&IF(AND(SUM($J13:$K13)<>$D13,SUM($J13:$K13)<>0),"gênero ","")&IF(AND(SUM($L13:$S13)<>$D13,SUM($L13:$S13)<>0),"professor","")))))
... A30: 46082 | B30: =IF($A30="","",CHOOSE(MONTH($A30),"Janeiro","Fevereiro","Março","Abril","Maio","Junho","Julho","Agosto","Setembro","Outubro","Novembro","Dezembro")) | C30: =IF($A30="","",CHOOSE(WEEKDAY($A30),"Domingo","Segunda-feira","Terça-feira","Quarta-feira","Quinta-feira","Sexta-feira","Sábado")) | E30: =IFERROR(INDEX(Consolidado_Mensal!$B$2:$B$12,MATCH($B30,Consolidado_Mensal!$A$2:$A$12,0)),"") | F30: =IF($E30="","",SUMIFS($D$2:$D30,$B$2:$B30,$B30)/$E30) | G30: =IF($E30="","",MAX(0,$E30-SUMIFS($D$2:$D30,$B$2:$B30,$B30))) | T30: =IF($D30="","",IF(AND($D30=0,SUM($H30:$S30)=0),"OK",IF(SUM($H30:$S30)=0,"Sem detalhe",IF(AND(OR(SUM($H30:$I30)=$D30,SUM($H30:$I30)=0),OR(SUM($J30:$K30)=$D30,SUM($J30:$K30)=0),OR(SUM($L30:$S30)=$D30,SUM($L30:$S30)=0)),"OK","Verificar: "&IF(AND(SUM($H30:$I30)<>$D30,SUM($H30:$I30)<>0),"perfil ","")&IF(AND(SUM($J30:$K30)<>$D30,SUM($J30:$K30)<>0),"gênero ","")&IF(AND(SUM($L30:$S30)<>$D30,SUM($L30:$S30)<>0),"professor","")))))
A31: 46083 | B31: =IF($A31="","",CHOOSE(MONTH($A31),"Janeiro","Fevereiro","Março","Abril","Maio","Junho","Julho","Agosto","Setembro","Outubro","Novembro","Dezembro")) | C31: =IF($A31="","",CHOOSE(WEEKDAY($A31),"Domingo","Segunda-feira","Terça-feira","Quarta-feira","Quinta-feira","Sexta-feira","Sábado")) | D31: 3 | E31: =IFERROR(INDEX(Consolidado_Mensal!$B$2:$B$12,MATCH($B31,Consolidado_Mensal!$A$2:$A$12,0)),"") | F31: =IF($E31="","",SUMIFS($D$2:$D31,$B$2:$B31,$B31)/$E31) | G31: =IF($E31="","",MAX(0,$E31-SUMIFS($D$2:$D31,$B$2:$B31,$B31))) | T31: =IF($D31="","",IF(AND($D31=0,SUM($H31:$S31)=0),"OK",IF(SUM($H31:$S31)=0,"Sem detalhe",IF(AND(OR(SUM($H31:$I31)=$D31,SUM($H31:$I31)=0),OR(SUM($J31:$K31)=$D31,SUM($J31:$K31)=0),OR(SUM($L31:$S31)=$D31,SUM($L31:$S31)=0)),"OK","Verificar: "&IF(AND(SUM($H31:$I31)<>$D31,SUM($H31:$I31)<>0),"perfil ","")&IF(AND(SUM($J31:$K31)<>$D31,SUM($J31:$K31)<>0),"gênero ","")&IF(AND(SUM($L31:$S31)<>$D31,SUM($L31:$S31)<>0),"professor","")))))
A32: 46084 | B32: =IF($A32="","",CHOOSE(MONTH($A32),"Janeiro","Fevereiro","Março","Abril","Maio","Junho","Julho","Agosto","Setembro","Outubro","Novembro","Dezembro")) | C32: =IF($A32="","",CHOOSE(WEEKDAY($A32),"Domingo","Segunda-feira","Terça-feira","Quarta-feira","Quinta-feira","Sexta-feira","Sábado")) | D32: 3 | E32: =IFERROR(INDEX(Consolidado_Mensal!$B$2:$B$12,MATCH($B32,Consolidado_Mensal!$A$2:$A$12,0)),"") | F32: =IF($E32="","",SUMIFS($D$2:$D32,$B$2:$B32,$B32)/$E32) | G32: =IF($E32="","",MAX(0,$E32-SUMIFS($D$2:$D32,$B$2:$B32,$B32))) | T32: =IF($D32="","",IF(AND($D32=0,SUM($H32:$S32)=0),"OK",IF(SUM($H32:$S32)=0,"Sem detalhe",IF(AND(OR(SUM($H32:$I32)=$D32,SUM($H32:$I32)=0),OR(SUM($J32:$K32)=$D32,SUM($J32:$K32)=0),OR(SUM($L32:$S32)=$D32,SUM($L32:$S32)=0)),"OK","Verificar: "&IF(AND(SUM($H32:$I32)<>$D32,SUM($H32:$I32)<>0),"perfil ","")&IF(AND(SUM($J32:$K32)<>$D32,SUM($J32:$K32)<>0),"gênero ","")&IF(AND(SUM($L32:$S32)<>$D32,SUM($L32:$S32)<>0),"professor","")))))
A33: 46085 | B33: =IF($A33="","",CHOOSE(MONTH($A33),"Janeiro","Fevereiro","Março","Abril","Maio","Junho","Julho","Agosto","Setembro","Outubro","Novembro","Dezembro")) | C33: =IF($A33="","",CHOOSE(WEEKDAY($A33),"Domingo","Segunda-feira","Terça-feira","Quarta-feira","Quinta-feira","Sexta-feira","Sábado")) | D33: 4 | E33: =IFERROR(INDEX(Consolidado_Mensal!$B$2:$B$12,MATCH($B33,Consolidado_Mensal!$A$2:$A$12,0)),"") | F33: =IF($E33="","",SUMIFS($D$2:$D33,$B$2:$B33,$B33)/$E33) | G33: =IF($E33="","",MAX(0,$E33-SUMIFS($D$2:$D33,$B$2:$B33,$B33))) | T33: =IF($D33="","",IF(AND($D33=0,SUM($H33:$S33)=0),"OK",IF(SUM($H33:$S33)=0,"Sem detalhe",IF(AND(OR(SUM($H33:$I33)=$D33,SUM($H33:$I33)=0),OR(SUM($J33:$K33)=$D33,SUM($J33:$K33)=0),OR(SUM($L33:$S33)=$D33,SUM($L33:$S33)=0)),"OK","Verificar: "&IF(AND(SUM($H33:$I33)<>$D33,SUM($H33:$I33)<>0),"perfil ","")&IF(AND(SUM($J33:$K33)<>$D33,SUM($J33:$K33)<>0),"gênero ","")&IF(AND(SUM($L33:$S33)<>$D33,SUM($L33:$S33)<>0),"professor","")))))
A34: 46086 | B34: =IF($A34="","",CHOOSE(MONTH($A34),"Janeiro","Fevereiro","Março","Abril","Maio","Junho","Julho","Agosto","Setembro","Outubro","Novembro","Dezembro")) | C34: =IF($A34="","",CHOOSE(WEEKDAY($A34),"Domingo","Segunda-feira","Terça-feira","Quarta-feira","Quinta-feira","Sexta-feira","Sábado")) | D34: 3 | E34: =IFERROR(INDEX(Consolidado_Mensal!$B$2:$B$12,MATCH($B34,Consolidado_Mensal!$A$2:$A$12,0)),"") | F34: =IF($E34="","",SUMIFS($D$2:$D34,$B$2:$B34,$B34)/$E34) | G34: =IF($E34="","",MAX(0,$E34-SUMIFS($D$2:$D34,$B$2:$B34,$B34))) | T34: =IF($D34="","",IF(AND($D34=0,SUM($H34:$S34)=0),"OK",IF(SUM($H34:$S34)=0,"Sem detalhe",IF(AND(OR(SUM($H34:$I34)=$D34,SUM($H34:$I34)=0),OR(SUM($J34:$K34)=$D34,SUM($J34:$K34)=0),OR(SUM($L34:$S34)=$D34,SUM($L34:$S34)=0)),"OK","Verificar: "&IF(AND(SUM($H34:$I34)<>$D34,SUM($H34:$I34)<>0),"perfil ","")&IF(AND(SUM($J34:$K34)<>$D34,SUM($J34:$K34)<>0),"gênero ","")&IF(AND(SUM($L34:$S34)<>$D34,SUM($L34:$S34)<>0),"professor","")))))
A35: 46087 | B35: =IF($A35="","",CHOOSE(MONTH($A35),"Janeiro","Fevereiro","Março","Abril","Maio","Junho","Julho","Agosto","Setembro","Outubro","Novembro","Dezembro")) | C35: =IF($A35="","",CHOOSE(WEEKDAY($A35),"Domingo","Segunda-feira","Terça-feira","Quarta-feira","Quinta-feira","Sexta-feira","Sábado")) | D35: 2 | E35: =IFERROR(INDEX(Consolidado_Mensal!$B$2:$B$12,MATCH($B35,Consolidado_Mensal!$A$2:$A$12,0)),"") | F35: =IF($E35="","",SUMIFS($D$2:$D35,$B$2:$B35,$B35)/$E35) | G35: =IF($E35="","",MAX(0,$E35-SUMIFS($D$2:$D35,$B$2:$B35,$B35))) | T35: =IF($D35="","",IF(AND($D35=0,SUM($H35:$S35)=0),"OK",IF(SUM($H35:$S35)=0,"Sem detalhe",IF(AND(OR(SUM($H35:$I35)=$D35,SUM($H35:$I35)=0),OR(SUM($J35:$K35)=$D35,SUM($J35:$K35)=0),OR(SUM($L35:$S35)=$D35,SUM($L35:$S35)=0)),"OK","Verificar: "&IF(AND(SUM($H35:$I35)<>$D35,SUM($H35:$I35)<>0),"perfil ","")&IF(AND(SUM($J35:$K35)<>$D35,SUM($J35:$K35)<>0),"gênero ","")&IF(AND(SUM($L35:$S35)<>$D35,SUM($L35:$S35)<>0),"professor","")))))
A36: 46088 | B36: =IF($A36="","",CHOOSE(MONTH($A36),"Janeiro","Fevereiro","Março","Abril","Maio","Junho","Julho","Agosto","Setembro","Outubro","Novembro","Dezembro")) | C36: =IF($A36="","",CHOOSE(WEEKDAY($A36),"Domingo","Segunda-feira","Terça-feira","Quarta-feira","Quinta-feira","Sexta-feira","Sábado")) | E36: =IFERROR(INDEX(Consolidado_Mensal!$B$2:$B$12,MATCH($B36,Consolidado_Mensal!$A$2:$A$12,0)),"") | F36: =IF($E36="","",SUMIFS($D$2:$D36,$B$2:$B36,$B36)/$E36) | G36: =IF($E36="","",MAX(0,$E36-SUMIFS($D$2:$D36,$B$2:$B36,$B36))) | T36: =IF($D36="","",IF(AND($D36=0,SUM($H36:$S36)=0),"OK",IF(SUM($H36:$S36)=0,"Sem detalhe",IF(AND(OR(SUM($H36:$I36)=$D36,SUM($H36:$I36)=0),OR(SUM($J36:$K36)=$D36,SUM($J36:$K36)=0),OR(SUM($L36:$S36)=$D36,SUM($L36:$S36)=0)),"OK","Verificar: "&IF(AND(SUM($H36:$I36)<>$D36,SUM($H36:$I36)<>0),"perfil ","")&IF(AND(SUM($J36:$K36)<>$D36,SUM($J36:$K36)<>0),"gênero ","")&IF(AND(SUM($L36:$S36)<>$D36,SUM($L36:$S36)<>0),"professor","")))))
A37: 46089 | B37: =IF($A37="","",CHOOSE(MONTH($A37),"Janeiro","Fevereiro","Março","Abril","Maio","Junho","Julho","Agosto","Setembro","Outubro","Novembro","Dezembro")) | C37: =IF($A37="","",CHOOSE(WEEKDAY($A37),"Domingo","Segunda-feira","Terça-feira","Quarta-feira","Quinta-feira","Sexta-feira","Sábado")) | E37: =IFERROR(INDEX(Consolidado_Mensal!$B$2:$B$12,MATCH($B37,Consolidado_Mensal!$A$2:$A$12,0)),"") | F37: =IF($E37="","",SUMIFS($D$2:$D37,$B$2:$B37,$B37)/$E37) | G37: =IF($E37="","",MAX(0,$E37-SUMIFS($D$2:$D37,$B$2:$B37,$B37))) | T37: =IF($D37="","",IF(AND($D37=0,SUM($H37:$S37)=0),"OK",IF(SUM($H37:$S37)=0,"Sem detalhe",IF(AND(OR(SUM($H37:$I37)=$D37,SUM($H37:$I37)=0),OR(SUM($J37:$K37)=$D37,SUM($J37:$K37)=0),OR(SUM($L37:$S37)=$D37,SUM($L37:$S37)=0)),"OK","Verificar: "&IF(AND(SUM($H37:$I37)<>$D37,SUM($H37:$I37)<>0),"perfil ","")&IF(AND(SUM($J37:$K37)<>$D37,SUM($J37:$K37)<>0),"gênero ","")&IF(AND(SUM($L37:$S37)<>$D37,SUM($L37:$S37)<>0),"professor","")))))
A38: 46090 | B38: =IF($A38="","",CHOOSE(MONTH($A38),"Janeiro","Fevereiro","Março","Abril","Maio","Junho","Julho","Agosto","Setembro","Outubro","Novembro","Dezembro")) | C38: =IF($A38="","",CHOOSE(WEEKDAY($A38),"Domingo","Segunda-feira","Terça-feira","Quarta-feira","Quinta-feira","Sexta-feira","Sábado")) | D38: 1 | E38: =IFERROR(INDEX(Consolidado_Mensal!$B$2:$B$12,MATCH($B38,Consolidado_Mensal!$A$2:$A$12,0)),"") | F38: =IF($E38="","",SUMIFS($D$2:$D38,$B$2:$B38,$B38)/$E38) | G38: =IF($E38="","",MAX(0,$E38-SUMIFS($D$2:$D38,$B$2:$B38,$B38))) | T38: =IF($D38="","",IF(AND($D38=0,SUM($H38:$S38)=0),"OK",IF(SUM($H38:$S38)=0,"Sem detalhe",IF(AND(OR(SUM($H38:$I38)=$D38,SUM($H38:$I38)=0),OR(SUM($J38:$K38)=$D38,SUM($J38:$K38)=0),OR(SUM($L38:$S38)=$D38,SUM($L38:$S38)=0)),"OK","Verificar: "&IF(AND(SUM($H38:$I38)<>$D38,SUM($H38:$I38)<>0),"perfil ","")&IF(AND(SUM($J38:$K38)<>$D38,SUM($J38:$K38)<>0),"gênero ","")&IF(AND(SUM($L38:$S38)<>$D38,SUM($L38:$S38)<>0),"professor","")))))
A39: 46091 | B39: =IF($A39="","",CHOOSE(MONTH($A39),"Janeiro","Fevereiro","Março","Abril","Maio","Junho","Julho","Agosto","Setembro","Outubro","Novembro","Dezembro")) | C39: =IF($A39="","",CHOOSE(WEEKDAY($A39),"Domingo","Segunda-feira","Terça-feira","Quarta-feira","Quinta-feira","Sexta-feira","Sábado")) | D39: 4 | E39: =IFERROR(INDEX(Consolidado_Mensal!$B$2:$B$12,MATCH($B39,Consolidado_Mensal!$A$2:$A$12,0)),"") | F39: =IF($E39="","",SUMIFS($D$2:$D39,$B$2:$B39,$B39)/$E39) | G39: =IF($E39="","",MAX(0,$E39-SUMIFS($D$2:$D39,$B$2:$B39,$B39))) | T39: =IF($D39="","",IF(AND($D39=0,SUM($H39:$S39)=0),"OK",IF(SUM($H39:$S39)=0,"Sem detalhe",IF(AND(OR(SUM($H39:$I39)=$D39,SUM($H39:$I39)=0),OR(SUM($J39:$K39)=$D39,SUM($J39:$K39)=0),OR(SUM($L39:$S39)=$D39,SUM($L39:$S39)=0)),"OK","Verificar: "&IF(AND(SUM($H39:$I39)<>$D39,SUM($H39:$I39)<>0),"perfil ","")&IF(AND(SUM($J39:$K39)<>$D39,SUM($J39:$K39)<>0),"gênero ","")&IF(AND(SUM($L39:$S39)<>$D39,SUM($L39:$S39)<>0),"professor","")))))
A40: 46092 | B40: =IF($A40="","",CHOOSE(MONTH($A40),"Janeiro","Fevereiro","Março","Abril","Maio","Junho","Julho","Agosto","Setembro","Outubro","Novembro","Dezembro")) | C40: =IF($A40="","",CHOOSE(WEEKDAY($A40),"Domingo","Segunda-feira","Terça-feira","Quarta-feira","Quinta-feira","Sexta-feira","Sábado")) | D40: 1 | E40: =IFERROR(INDEX(Consolidado_Mensal!$B$2:$B$12,MATCH($B40,Consolidado_Mensal!$A$2:$A$12,0)),"") | F40: =IF($E40="","",SUMIFS($D$2:$D40,$B$2:$B40,$B40)/$E40) | G40: =IF($E40="","",MAX(0,$E40-SUMIFS($D$2:$D40,$B$2:$B40,$B40))) | T40: =IF($D40="","",IF(AND($D40=0,SUM($H40:$S40)=0),"OK",IF(SUM($H40:$S40)=0,"Sem detalhe",IF(AND(OR(SUM($H40:$I40)=$D40,SUM($H40:$I40)=0),OR(SUM($J40:$K40)=$D40,SUM($J40:$K40)=0),OR(SUM($L40:$S40)=$D40,SUM($L40:$S40)=0)),"OK","Verificar: "&IF(AND(SUM($H40:$I40)<>$D40,SUM($H40:$I40)<>0),"perfil ","")&IF(AND(SUM($J40:$K40)<>$D40,SUM($J40:$K40)<>0),"gênero ","")&IF(AND(SUM($L40:$S40)<>$D40,SUM($L40:$S40)<>0),"professor","")))))
A41: 46093 | B41: =IF($A41="","",CHOOSE(MONTH($A41),"Janeiro","Fevereiro","Março","Abril","Maio","Junho","Julho","Agosto","Setembro","Outubro","Novembro","Dezembro")) | C41: =IF($A41="","",CHOOSE(WEEKDAY($A41),"Domingo","Segunda-feira","Terça-feira","Quarta-feira","Quinta-feira","Sexta-feira","Sábado")) | D41: 4 | E41: =IFERROR(INDEX(Consolidado_Mensal!$B$2:$B$12,MATCH($B41,Consolidado_Mensal!$A$2:$A$12,0)),"") | F41: =IF($E41="","",SUMIFS($D$2:$D41,$B$2:$B41,$B41)/$E41) | G41: =IF($E41="","",MAX(0,$E41-SUMIFS($D$2:$D41,$B$2:$B41,$B41))) | T41: =IF($D41="","",IF(AND($D41=0,SUM($H41:$S41)=0),"OK",IF(SUM($H41:$S41)=0,"Sem detalhe",IF(AND(OR(SUM($H41:$I41)=$D41,SUM($H41:$I41)=0),OR(SUM($J41:$K41)=$D41,SUM($J41:$K41)=0),OR(SUM($L41:$S41)=$D41,SUM($L41:$S41)=0)),"OK","Verificar: "&IF(AND(SUM($H41:$I41)<>$D41,SUM($H41:$I41)<>0),"perfil ","")&IF(AND(SUM($J41:$K41)<>$D41,SUM($J41:$K41)<>0),"gênero ","")&IF(AND(SUM($L41:$S41)<>$D41,SUM($L41:$S41)<>0),"professor","")))))
A42: 46094 | B42: =IF($A42="","",CHOOSE(MONTH($A42),"Janeiro","Fevereiro","Março","Abril","Maio","Junho","Julho","Agosto","Setembro","Outubro","Novembro","Dezembro")) | C42: =IF($A42="","",CHOOSE(WEEKDAY($A42),"Domingo","Segunda-feira","Terça-feira","Quarta-feira","Quinta-feira","Sexta-feira","Sábado")) | E42: =IFERROR(INDEX(Consolidado_Mensal!$B$2:$B$12,MATCH($B42,Consolidado_Mensal!$A$2:$A$12,0)),"") | F42: =IF($E42="","",SUMIFS($D$2:$D42,$B$2:$B42,$B42)/$E42) | G42: =IF($E42="","",MAX(0,$E42-SUMIFS($D$2:$D42,$B$2:$B42,$B42))) | T42: =IF($D42="","",IF(AND($D42=0,SUM($H42:$S42)=0),"OK",IF(SUM($H42:$S42)=0,"Sem detalhe",IF(AND(OR(SUM($H42:$I42)=$D42,SUM($H42:$I42)=0),OR(SUM($J42:$K42)=$D42,SUM($J42:$K42)=0),OR(SUM($L42:$S42)=$D42,SUM($L42:$S42)=0)),"OK","Verificar: "&IF(AND(SUM($H42:$I42)<>$D42,SUM($H42:$I42)<>0),"perfil ","")&IF(AND(SUM($J42:$K42)<>$D42,SUM($J42:$K42)<>0),"gênero ","")&IF(AND(SUM($L42:$S42)<>$D42,SUM($L42:$S42)<>0),"professor","")))))
A43: 46095 | B43: =IF($A43="","",CHOOSE(MONTH($A43),"Janeiro","Fevereiro","Março","Abril","Maio","Junho","Julho","Agosto","Setembro","Outubro","Novembro","Dezembro")) | C43: =IF($A43="","",CHOOSE(WEEKDAY($A43),"Domingo","Segunda-feira","Terça-feira","Quarta-feira","Quinta-feira","Sexta-feira","Sábado")) | E43: =IFERROR(INDEX(Consolidado_Mensal!$B$2:$B$12,MATCH($B43,Consolidado_Mensal!$A$2:$A$12,0)),"") | F43: =IF($E43="","",SUMIFS($D$2:$D43,$B$2:$B43,$B43)/$E43) | G43: =IF($E43="","",MAX(0,$E43-SUMIFS($D$2:$D43,$B$2:$B43,$B43))) | T43: =IF($D43="","",IF(AND($D43=0,SUM($H43:$S43)=0),"OK",IF(SUM($H43:$S43)=0,"Sem detalhe",IF(AND(OR(SUM($H43:$I43)=$D43,SUM($H43:$I43)=0),OR(SUM($J43:$K43)=$D43,SUM($J43:$K43)=0),OR(SUM($L43:$S43)=$D43,SUM($L43:$S43)=0)),"OK","Verificar: "&IF(AND(SUM($H43:$I43)<>$D43,SUM($H43:$I43)<>0),"perfil ","")&IF(AND(SUM($J43:$K43)<>$D43,SUM($J43:$K43)<>0),"gênero ","")&IF(AND(SUM($L43:$S43)<>$D43,SUM($L43:$S43)<>0),"professor","")))))
A44: 46096 | B44: =IF($A44="","",CHOOSE(MONTH($A44),"Janeiro","Fevereiro","Março","Abril","Maio","Junho","Julho","Agosto","Setembro","Outubro","Novembro","Dezembro")) | C44: =IF($A44="","",CHOOSE(WEEKDAY($A44),"Domingo","Segunda-feira","Terça-feira","Quarta-feira","Quinta-feira","Sexta-feira","Sábado")) | E44: =IFERROR(INDEX(Consolidado_Mensal!$B$2:$B$12,MATCH($B44,Consolidado_Mensal!$A$2:$A$12,0)),"") | F44: =IF($E44="","",SUMIFS($D$2:$D44,$B$2:$B44,$B44)/$E44) | G44: =IF($E44="","",MAX(0,$E44-SUMIFS($D$2:$D44,$B$2:$B44,$B44))) | T44: =IF($D44="","",IF(AND($D44=0,SUM($H44:$S44)=0),"OK",IF(SUM($H44:$S44)=0,"Sem detalhe",IF(AND(OR(SUM($H44:$I44)=$D44,SUM($H44:$I44)=0),OR(SUM($J44:$K44)=$D44,SUM($J44:$K44)=0),OR(SUM($L44:$S44)=$D44,SUM($L44:$S44)=0)),"OK","Verificar: "&IF(AND(SUM($H44:$I44)<>$D44,SUM($H44:$I44)<>0),"perfil ","")&IF(AND(SUM($J44:$K44)<>$D44,SUM($J44:$K44)<>0),"gênero ","")&IF(AND(SUM($L44:$S44)<>$D44,SUM($L44:$S44)<>0),"professor","")))))
A45: 46097 | B45: =IF($A45="","",CHOOSE(MONTH($A45),"Janeiro","Fevereiro","Março","Abril","Maio","Junho","Julho","Agosto","Setembro","Outubro","Novembro","Dezembro")) | C45: =IF($A45="","",CHOOSE(WEEKDAY($A45),"Domingo","Segunda-feira","Terça-feira","Quarta-feira","Quinta-feira","Sexta-feira","Sábado")) | D45: 3 | E45: =IFERROR(INDEX(Consolidado_Mensal!$B$2:$B$12,MATCH($B45,Consolidado_Mensal!$A$2:$A$12,0)),"") | F45: =IF($E45="","",SUMIFS($D$2:$D45,$B$2:$B45,$B45)/$E45) | G45: =IF($E45="","",MAX(0,$E45-SUMIFS($D$2:$D45,$B$2:$B45,$B45))) | T45: =IF($D45="","",IF(AND($D45=0,SUM($H45:$S45)=0),"OK",IF(SUM($H45:$S45)=0,"Sem detalhe",IF(AND(OR(SUM($H45:$I45)=$D45,SUM($H45:$I45)=0),OR(SUM($J45:$K45)=$D45,SUM($J45:$K45)=0),OR(SUM($L45:$S45)=$D45,SUM($L45:$S45)=0)),"OK","Verificar: "&IF(AND(SUM($H45:$I45)<>$D45,SUM($H45:$I45)<>0),"perfil ","")&IF(AND(SUM($J45:$K45)<>$D45,SUM($J45:$K45)<>0),"gênero ","")&IF(AND(SUM($L45:$S45)<>$D45,SUM($L45:$S45)<>0),"professor","")))))
A46: 46098 | B46: =IF($A46="","",CHOOSE(MONTH($A46),"Janeiro","Fevereiro","Março","Abril","Maio","Junho","Julho","Agosto","Setembro","Outubro","Novembro","Dezembro")) | C46: =IF($A46="","",CHOOSE(WEEKDAY($A46),"Domingo","Segunda-feira","Terça-feira","Quarta-feira","Quinta-feira","Sexta-feira","Sábado")) | D46: 4 | E46: =IFERROR(INDEX(Consolidado_Mensal!$B$2:$B$12,MATCH($B46,Consolidado_Mensal!$A$2:$A$12,0)),"") | F46: =IF($E46="","",SUMIFS($D$2:$D46,$B$2:$B46,$B46)/$E46) | G46: =IF($E46="","",MAX(0,$E46-SUMIFS($D$2:$D46,$B$2:$B46,$B46))) | T46: =IF($D46="","",IF(AND($D46=0,SUM($H46:$S46)=0),"OK",IF(SUM($H46:$S46)=0,"Sem detalhe",IF(AND(OR(SUM($H46:$I46)=$D46,SUM($H46:$I46)=0),OR(SUM($J46:$K46)=$D46,SUM($J46:$K46)=0),OR(SUM($L46:$S46)=$D46,SUM($L46:$S46)=0)),"OK","Verificar: "&IF(AND(SUM($H46:$I46)<>$D46,SUM($H46:$I46)<>0),"perfil ","")&IF(AND(SUM($J46:$K46)<>$D46,SUM($J46:$K46)<>0),"gênero ","")&IF(AND(SUM($L46:$S46)<>$D46,SUM($L46:$S46)<>0),"professor","")))))
A47: 46099 | B47: =IF($A47="","",CHOOSE(MONTH($A47),"Janeiro","Fevereiro","Março","Abril","Maio","Junho","Julho","Agosto","Setembro","Outubro","Novembro","Dezembro")) | C47: =IF($A47="","",CHOOSE(WEEKDAY($A47),"Domingo","Segunda-feira","Terça-feira","Quarta-feira","Quinta-feira","Sexta-feira","Sábado")) | D47: 4 | E47: =IFERROR(INDEX(Consolidado_Mensal!$B$2:$B$12,MATCH($B47,Consolidado_Mensal!$A$2:$A$12,0)),"") | F47: =IF($E47="","",SUMIFS($D$2:$D47,$B$2:$B47,$B47)/$E47) | G47: =IF($E47="","",MAX(0,$E47-SUMIFS($D$2:$D47,$B$2:$B47,$B47))) | T47: =IF($D47="","",IF(AND($D47=0,SUM($H47:$S47)=0),"OK",IF(SUM($H47:$S47)=0,"Sem detalhe",IF(AND(OR(SUM($H47:$I47)=$D47,SUM($H47:$I47)=0),OR(SUM($J47:$K47)=$D47,SUM($J47:$K47)=0),OR(SUM($L47:$S47)=$D47,SUM($L47:$S47)=0)),"OK","Verificar: "&IF(AND(SUM($H47:$I47)<>$D47,SUM($H47:$I47)<>0),"perfil ","")&IF(AND(SUM($J47:$K47)<>$D47,SUM($J47:$K47)<>0),"gênero ","")&IF(AND(SUM($L47:$S47)<>$D47,SUM($L47:$S47)<>0),"professor","")))))
A48: 46100 | B48: =IF($A48="","",CHOOSE(MONTH($A48),"Janeiro","Fevereiro","Março","Abril","Maio","Junho","Julho","Agosto","Setembro","Outubro","Novembro","Dezembro")) | C48: =IF($A48="","",CHOOSE(WEEKDAY($A48),"Domingo","Segunda-feira","Terça-feira","Quarta-feira","Quinta-feira","Sexta-feira","Sábado")) | D48: 1 | E48: =IFERROR(INDEX(Consolidado_Mensal!$B$2:$B$12,MATCH($B48,Consolidado_Mensal!$A$2:$A$12,0)),"") | F48: =IF($E48="","",SUMIFS($D$2:$D48,$B$2:$B48,$B48)/$E48) | G48: =IF($E48="","",MAX(0,$E48-SUMIFS($D$2:$D48,$B$2:$B48,$B48))) | T48: =IF($D48="","",IF(AND($D48=0,SUM($H48:$S48)=0),"OK",IF(SUM($H48:$S48)=0,"Sem detalhe",IF(AND(OR(SUM($H48:$I48)=$D48,SUM($H48:$I48)=0),OR(SUM($J48:$K48)=$D48,SUM($J48:$K48)=0),OR(SUM($L48:$S48)=$D48,SUM($L48:$S48)=0)),"OK","Verificar: "&IF(AND(SUM($H48:$I48)<>$D48,SUM($H48:$I48)<>0),"perfil ","")&IF(AND(SUM($J48:$K48)<>$D48,SUM($J48:$K48)<>0),"gênero ","")&IF(AND(SUM($L48:$S48)<>$D48,SUM($L48:$S48)<>0),"professor","")))))
A49: 46101 | B49: =IF($A49="","",CHOOSE(MONTH($A49),"Janeiro","Fevereiro","Março","Abril","Maio","Junho","Julho","Agosto","Setembro","Outubro","Novembro","Dezembro")) | C49: =IF($A49="","",CHOOSE(WEEKDAY($A49),"Domingo","Segunda-feira","Terça-feira","Quarta-feira","Quinta-feira","Sexta-feira","Sábado")) | E49: =IFERROR(INDEX(Consolidado_Mensal!$B$2:$B$12,MATCH($B49,Consolidado_Mensal!$A$2:$A$12,0)),"") | F49: =IF($E49="","",SUMIFS($D$2:$D49,$B$2:$B49,$B49)/$E49) | G49: =IF($E49="","",MAX(0,$E49-SUMIFS($D$2:$D49,$B$2:$B49,$B49))) | T49: =IF($D49="","",IF(AND($D49=0,SUM($H49:$S49)=0),"OK",IF(SUM($H49:$S49)=0,"Sem detalhe",IF(AND(OR(SUM($H49:$I49)=$D49,SUM($H49:$I49)=0),OR(SUM($J49:$K49)=$D49,SUM($J49:$K49)=0),OR(SUM($L49:$S49)=$D49,SUM($L49:$S49)=0)),"OK","Verificar: "&IF(AND(SUM($H49:$I49)<>$D49,SUM($H49:$I49)<>0),"perfil ","")&IF(AND(SUM($J49:$K49)<>$D49,SUM($J49:$K49)<>0),"gênero ","")&IF(AND(SUM($L49:$S49)<>$D49,SUM($L49:$S49)<>0),"professor","")))))
A50: 46102 | B50: =IF($A50="","",CHOOSE(MONTH($A50),"Janeiro","Fevereiro","Março","Abril","Maio","Junho","Julho","Agosto","Setembro","Outubro","Novembro","Dezembro")) | C50: =IF($A50="","",CHOOSE(WEEKDAY($A50),"Domingo","Segunda-feira","Terça-feira","Quarta-feira","Quinta-feira","Sexta-feira","Sábado")) | E50: =IFERROR(INDEX(Consolidado_Mensal!$B$2:$B$12,MATCH($B50,Consolidado_Mensal!$A$2:$A$12,0)),"") | F50: =IF($E50="","",SUMIFS($D$2:$D50,$B$2:$B50,$B50)/$E50) | G50: =IF($E50="","",MAX(0,$E50-SUMIFS($D$2:$D50,$B$2:$B50,$B50))) | T50: =IF($D50="","",IF(AND($D50=0,SUM($H50:$S50)=0),"OK",IF(SUM($H50:$S50)=0,"Sem detalhe",IF(AND(OR(SUM($H50:$I50)=$D50,SUM($H50:$I50)=0),OR(SUM($J50:$K50)=$D50,SUM($J50:$K50)=0),OR(SUM($L50:$S50)=$D50,SUM($L50:$S50)=0)),"OK","Verificar: "&IF(AND(SUM($H50:$I50)<>$D50,SUM($H50:$I50)<>0),"perfil ","")&IF(AND(SUM($J50:$K50)<>$D50,SUM($J50:$K50)<>0),"gênero ","")&IF(AND(SUM($L50:$S50)<>$D50,SUM($L50:$S50)<>0),"professor","")))))
A51: 46103 | B51: =IF($A51="","",CHOOSE(MONTH($A51),"Janeiro","Fevereiro","Março","Abril","Maio","Junho","Julho","Agosto","Setembro","Outubro","Novembro","Dezembro")) | C51: =IF($A51="","",CHOOSE(WEEKDAY($A51),"Domingo","Segunda-feira","Terça-feira","Quarta-feira","Quinta-feira","Sexta-feira","Sábado")) | E51: =IFERROR(INDEX(Consolidado_Mensal!$B$2:$B$12,MATCH($B51,Consolidado_Mensal!$A$2:$A$12,0)),"") | F51: =IF($E51="","",SUMIFS($D$2:$D51,$B$2:$B51,$B51)/$E51) | G51: =IF($E51="","",MAX(0,$E51-SUMIFS($D$2:$D51,$B$2:$B51,$B51))) | T51: =IF($D51="","",IF(AND($D51=0,SUM($H51:$S51)=0),"OK",IF(SUM($H51:$S51)=0,"Sem detalhe",IF(AND(OR(SUM($H51:$I51)=$D51,SUM($H51:$I51)=0),OR(SUM($J51:$K51)=$D51,SUM($J51:$K51)=0),OR(SUM($L51:$S51)=$D51,SUM($L51:$S51)=0)),"OK","Verificar: "&IF(AND(SUM($H51:$I51)<>$D51,SUM($H51:$I51)<>0),"perfil ","")&IF(AND(SUM($J51:$K51)<>$D51,SUM($J51:$K51)<>0),"gênero ","")&IF(AND(SUM($L51:$S51)<>$D51,SUM($L51:$S51)<>0),"professor","")))))
A52: 46104 | B52: =IF($A52="","",CHOOSE(MONTH($A52),"Janeiro","Fevereiro","Março","Abril","Maio","Junho","Julho","Agosto","Setembro","Outubro","Novembro","Dezembro")) | C52: =IF($A52="","",CHOOSE(WEEKDAY($A52),"Domingo","Segunda-feira","Terça-feira","Quarta-feira","Quinta-feira","Sexta-feira","Sábado")) | E52: =IFERROR(INDEX(Consolidado_Mensal!$B$2:$B$12,MATCH($B52,Consolidado_Mensal!$A$2:$A$12,0)),"") | F52: =IF($E52="","",SUMIFS($D$2:$D52,$B$2:$B52,$B52)/$E52) | G52: =IF($E52="","",MAX(0,$E52-SUMIFS($D$2:$D52,$B$2:$B52,$B52))) | T52: =IF($D52="","",IF(AND($D52=0,SUM($H52:$S52)=0),"OK",IF(SUM($H52:$S52)=0,"Sem detalhe",IF(AND(OR(SUM($H52:$I52)=$D52,SUM($H52:$I52)=0),OR(SUM($J52:$K52)=$D52,SUM($J52:$K52)=0),OR(SUM($L52:$S52)=$D52,SUM($L52:$S52)=0)),"OK","Verificar: "&IF(AND(SUM($H52:$I52)<>$D52,SUM($H52:$I52)<>0),"perfil ","")&IF(AND(SUM($J52:$K52)<>$D52,SUM($J52:$K52)<>0),"gênero ","")&IF(AND(SUM($L52:$S52)<>$D52,SUM($L52:$S52)<>0),"professor","")))))
A53: 46105 | B53: =IF($A53="","",CHOOSE(MONTH($A53),"Janeiro","Fevereiro","Março","Abril","Maio","Junho","Julho","Agosto","Setembro","Outubro","Novembro","Dezembro")) | C53: =IF($A53="","",CHOOSE(WEEKDAY($A53),"Domingo","Segunda-feira","Terça-feira","Quarta-feira","Quinta-feira","Sexta-feira","Sábado")) | D53: 2 | E53: =IFERROR(INDEX(Consolidado_Mensal!$B$2:$B$12,MATCH($B53,Consolidado_Mensal!$A$2:$A$12,0)),"") | F53: =IF($E53="","",SUMIFS($D$2:$D53,$B$2:$B53,$B53)/$E53) | G53: =IF($E53="","",MAX(0,$E53-SUMIFS($D$2:$D53,$B$2:$B53,$B53))) | T53: =IF($D53="","",IF(AND($D53=0,SUM($H53:$S53)=0),"OK",IF(SUM($H53:$S53)=0,"Sem detalhe",IF(AND(OR(SUM($H53:$I53)=$D53,SUM($H53:$I53)=0),OR(SUM($J53:$K53)=$D53,SUM($J53:$K53)=0),OR(SUM($L53:$S53)=$D53,SUM($L53:$S53)=0)),"OK","Verificar: "&IF(AND(SUM($H53:$I53)<>$D53,SUM($H53:$I53)<>0),"perfil ","")&IF(AND(SUM($J53:$K53)<>$D53,SUM($J53:$K53)<>0),"gênero ","")&IF(AND(SUM($L53:$S53)<>$D53,SUM($L53:$S53)<>0),"professor","")))))
A54: 46106 | B54: =IF($A54="","",CHOOSE(MONTH($A54),"Janeiro","Fevereiro","Março","Abril","Maio","Junho","Julho","Agosto","Setembro","Outubro","Novembro","Dezembro")) | C54: =IF($A54="","",CHOOSE(WEEKDAY($A54),"Domingo","Segunda-feira","Terça-feira","Quarta-feira","Quinta-feira","Sexta-feira","Sábado")) | D54: 1 | E54: =IFERROR(INDEX(Consolidado_Mensal!$B$2:$B$12,MATCH($B54,Consolidado_Mensal!$A$2:$A$12,0)),"") | F54: =IF($E54="","",SUMIFS($D$2:$D54,$B$2:$B54,$B54)/$E54) | G54: =IF($E54="","",MAX(0,$E54-SUMIFS($D$2:$D54,$B$2:$B54,$B54))) | T54: =IF($D54="","",IF(AND($D54=0,SUM($H54:$S54)=0),"OK",IF(SUM($H54:$S54)=0,"Sem detalhe",IF(AND(OR(SUM($H54:$I54)=$D54,SUM($H54:$I54)=0),OR(SUM($J54:$K54)=$D54,SUM($J54:$K54)=0),OR(SUM($L54:$S54)=$D54,SUM($L54:$S54)=0)),"OK","Verificar: "&IF(AND(SUM($H54:$I54)<>$D54,SUM($H54:$I54)<>0),"perfil ","")&IF(AND(SUM($J54:$K54)<>$D54,SUM($J54:$K54)<>0),"gênero ","")&IF(AND(SUM($L54:$S54)<>$D54,SUM($L54:$S54)<>0),"professor","")))))
A55: 46107 | B55: =IF($A55="","",CHOOSE(MONTH($A55),"Janeiro","Fevereiro","Março","Abril","Maio","Junho","Julho","Agosto","Setembro","Outubro","Novembro","Dezembro")) | C55: =IF($A55="","",CHOOSE(WEEKDAY($A55),"Domingo","Segunda-feira","Terça-feira","Quarta-feira","Quinta-feira","Sexta-feira","Sábado")) | D55: 1 | E55: =IFERROR(INDEX(Consolidado_Mensal!$B$2:$B$12,MATCH($B55,Consolidado_Mensal!$A$2:$A$12,0)),"") | F55: =IF($E55="","",SUMIFS($D$2:$D55,$B$2:$B55,$B55)/$E55) | G55: =IF($E55="","",MAX(0,$E55-SUMIFS($D$2:$D55,$B$2:$B55,$B55))) | T55: =IF($D55="","",IF(AND($D55=0,SUM($H55:$S55)=0),"OK",IF(SUM($H55:$S55)=0,"Sem detalhe",IF(AND(OR(SUM($H55:$I55)=$D55,SUM($H55:$I55)=0),OR(SUM($J55:$K55)=$D55,SUM($J55:$K55)=0),OR(SUM($L55:$S55)=$D55,SUM($L55:$S55)=0)),"OK","Verificar: "&IF(AND(SUM($H55:$I55)<>$D55,SUM($H55:$I55)<>0),"perfil ","")&IF(AND(SUM($J55:$K55)<>$D55,SUM($J55:$K55)<>0),"gênero ","")&IF(AND(SUM($L55:$S55)<>$D55,SUM($L55:$S55)<>0),"professor","")))))
A56: 46108 | B56: =IF($A56="","",CHOOSE(MONTH($A56),"Janeiro","Fevereiro","Março","Abril","Maio","Junho","Julho","Agosto","Setembro","Outubro","Novembro","Dezembro")) | C56: =IF($A56="","",CHOOSE(WEEKDAY($A56),"Domingo","Segunda-feira","Terça-feira","Quarta-feira","Quinta-feira","Sexta-feira","Sábado")) | E56: =IFERROR(INDEX(Consolidado_Mensal!$B$2:$B$12,MATCH($B56,Consolidado_Mensal!$A$2:$A$12,0)),"") | F56: =IF($E56="","",SUMIFS($D$2:$D56,$B$2:$B56,$B56)/$E56) | G56: =IF($E56="","",MAX(0,$E56-SUMIFS($D$2:$D56,$B$2:$B56,$B56))) | T56: =IF($D56="","",IF(AND($D56=0,SUM($H56:$S56)=0),"OK",IF(SUM($H56:$S56)=0,"Sem detalhe",IF(AND(OR(SUM($H56:$I56)=$D56,SUM($H56:$I56)=0),OR(SUM($J56:$K56)=$D56,SUM($J56:$K56)=0),OR(SUM($L56:$S56)=$D56,SUM($L56:$S56)=0)),"OK","Verificar: "&IF(AND(SUM($H56:$I56)<>$D56,SUM($H56:$I56)<>0),"perfil ","")&IF(AND(SUM($J56:$K56)<>$D56,SUM($J56:$K56)<>0),"gênero ","")&IF(AND(SUM($L56:$S56)<>$D56,SUM($L56:$S56)<>0),"professor","")))))
...

Sheet Histórico_Manual
A1: Mês | B1: Total | C1: Mulheres | D1: Homens | E1: Já Matriculados | F1: Aluno Novo | G1: Lucas | H1: Edy | I1: Eduardo | J1: Luiz | K1: Maria | L1: Observação
A2: Fevereiro | B2: 29 | G2: 15 | H2: 14 | L2: Sem diário: só o total do mês e o total por professor
A3: Março | G3: 22 | H3: 19 | I3: 1 | J3: 1 | K3: 1 | L3: Diário tem a quantidade por dia; professor só no total do mês (44 de 49 identificados)
A4: Abril | G4: 25 | H4: 19 | J4: 1 | K4: 4 | L4: Professor só no total do mês (49 de 50 identificados)
A5: Maio | C5: 23 | D5: 13 | G5: 16 | H5: 14 | I5: 3 | K5: 3 | L5: Gênero e professor só no total do mês
A6: Junho | G6: 18 | H6: 21 | J6: 1 | K6: 3 | L6: Gênero e perfil estão no diário; professor só no total do mês
A8: Regra: o Consolidado soma o diário MAIS esta aba. Só ponha aqui o que NÃO está lançado dia a dia, para não contar duas vezes.

Sheet Consolidado_Mensal
A1: Mês | B1: Meta | C1: Total | D1: % Meta | E1: Saldo | F1: Falta/dia | G1: M | H1: H | I1: =Diário_Avaliações!L$1 | J1: =Diário_Avaliações!M$1 | K1: =Diário_Avaliações!N$1 | L1: =Diário_Avaliações!O$1 | M1: =Diário_Avaliações!P$1 | N1: =Diário_Avaliações!Q$1 | O1: =Diário_Avaliações!R$1 | P1: =Diário_Avaliações!S$1 | Q1: Matric. | R1: Novo | S1: Origem dos dados | T1: Sem prof. identif. | U1: Nº Mês | V1: Dias restantes
A2: Fevereiro | B2: 50 | C2: =SUMIF(Diário_Avaliações!$B:$B,$A2,Diário_Avaliações!$D:$D)+IFERROR(INDEX(Histórico_Manual!$B:$B,MATCH($A2,Histórico_Manual!$A:$A,0)),0) | D2: =IF($B2=0,"",$C2/$B2) | E2: =$C2-$B2 | F2: =IF($C2>=$B2,0,IF($V2=0,"",ROUND(($B2-$C2)/$V2,1))) | G2: =SUMIF(Diário_Avaliações!$B:$B,$A2,Diário_Avaliações!$K:$K)+IFERROR(INDEX(Histórico_Manual!$C:$C,MATCH($A2,Histórico_Manual!$A:$A,0)),0) | H2: =SUMIF(Diário_Avaliações!$B:$B,$A2,Diário_Avaliações!$J:$J)+IFERROR(INDEX(Histórico_Manual!$D:$D,MATCH($A2,Histórico_Manual!$A:$A,0)),0) | I2: =IF(OR(I$1="",I$1="(livre)"),"",IFERROR(SUMIF(Diário_Avaliações!$B:$B,$A2,INDEX(Diário_Avaliações!$L:$S,0,MATCH(I$1,Diário_Avaliações!$L$1:$S$1,0))),0)+IFERROR(INDEX(Histórico_Manual!$G:$K,MATCH($A2,Histórico_Manual!$A:$A,0),MATCH(I$1,Histórico_Manual!$G$1:$K$1,0)),0)) | J2: =IF(OR(J$1="",J$1="(livre)"),"",IFERROR(SUMIF(Diário_Avaliações!$B:$B,$A2,INDEX(Diário_Avaliações!$L:$S,0,MATCH(J$1,Diário_Avaliações!$L$1:$S$1,0))),0)+IFERROR(INDEX(Histórico_Manual!$G:$K,MATCH($A2,Histórico_Manual!$A:$A,0),MATCH(J$1,Histórico_Manual!$G$1:$K$1,0)),0)) | K2: =IF(OR(K$1="",K$1="(livre)"),"",IFERROR(SUMIF(Diário_Avaliações!$B:$B,$A2,INDEX(Diário_Avaliações!$L:$S,0,MATCH(K$1,Diário_Avaliações!$L$1:$S$1,0))),0)+IFERROR(INDEX(Histórico_Manual!$G:$K,MATCH($A2,Histórico_Manual!$A:$A,0),MATCH(K$1,Histórico_Manual!$G$1:$K$1,0)),0)) | L2: =IF(OR(L$1="",L$1="(livre)"),"",IFERROR(SUMIF(Diário_Avaliações!$B:$B,$A2,INDEX(Diário_Avaliações!$L:$S,0,MATCH(L$1,Diário_Avaliações!$L$1:$S$1,0))),0)+IFERROR(INDEX(Histórico_Manual!$G:$K,MATCH($A2,Histórico_Manual!$A:$A,0),MATCH(L$1,Histórico_Manual!$G$1:$K$1,0)),0)) | M2: =IF(OR(M$1="",M$1="(livre)"),"",IFERROR(SUMIF(Diário_Avaliações!$B:$B,$A2,INDEX(Diário_Avaliações!$L:$S,0,MATCH(M$1,Diário_Avaliações!$L$1:$S$1,0))),0)+IFERROR(INDEX(Histórico_Manual!$G:$K,MATCH($A2,Histórico_Manual!$A:$A,0),MATCH(M$1,Histórico_Manual!$G$1:$K$1,0)),0)) | N2: =IF(OR(N$1="",N$1="(livre)"),"",IFERROR(SUMIF(Diário_Avaliações!$B:$B,$A2,INDEX(Diário_Avaliações!$L:$S,0,MATCH(N$1,Diário_Avaliações!$L$1:$S$1,0))),0)+IFERROR(INDEX(Histórico_Manual!$G:$K,MATCH($A2,Histórico_Manual!$A:$A,0),MATCH(N$1,Histórico_Manual!$G$1:$K$1,0)),0)) | O2: =IF(OR(O$1="",O$1="(livre)"),"",IFERROR(SUMIF(Diário_Avaliações!$B:$B,$A2,INDEX(Diário_Avaliações!$L:$S,0,MATCH(O$1,Diário_Avaliações!$L$1:$S$1,0))),0)+IFERROR(INDEX(Histórico_Manual!$G:$K,MATCH($A2,Histórico_Manual!$A:$A,0),MATCH(O$1,Histórico_Manual!$G$1:$K$1,0)),0)) | P2: =IF(OR(P$1="",P$1="(livre)"),"",IFERROR(SUMIF(Diário_Avaliações!$B:$B,$A2,INDEX(Diário_Avaliações!$L:$S,0,MATCH(P$1,Diário_Avaliações!$L$1:$S$1,0))),0)+IFERROR(INDEX(Histórico_Manual!$G:$K,MATCH($A2,Histórico_Manual!$A:$A,0),MATCH(P$1,Histórico_Manual!$G$1:$K$1,0)),0)) | Q2: =SUMIF(Diário_Avaliações!$B:$B,$A2,Diário_Avaliações!$H:$H)+IFERROR(INDEX(Histórico_Manual!$E:$E,MATCH($A2,Histórico_Manual!$A:$A,0)),0) | R2: =SUMIF(Diário_Avaliações!$B:$B,$A2,Diário_Avaliações!$I:$I)+IFERROR(INDEX(Histórico_Manual!$F:$F,MATCH($A2,Histórico_Manual!$A:$A,0)),0) | S2: =IF($C2=0,"—",IF(SUMIF(Diário_Avaliações!$B:$B,$A2,Diário_Avaliações!$D:$D)=0,"Manual",IF(ISNUMBER(MATCH($A2,Histórico_Manual!$A:$A,0)),"Diário + manual","Diário"))) | T2: =IF($C2=0,"",$C2-SUM($I2:$P2)) | U2: 2 | V2: =MAX(0,DATE(2026,2,28)-MAX(TODAY(),DATE(2026,2,1))+1)
A3: Março | B3: 50 | C3: =SUMIF(Diário_Avaliações!$B:$B,$A3,Diário_Avaliações!$D:$D)+IFERROR(INDEX(Histórico_Manual!$B:$B,MATCH($A3,Histórico_Manual!$A:$A,0)),0) | D3: =IF($B3=0,"",$C3/$B3) | E3: =$C3-$B3 | F3: =IF($C3>=$B3,0,IF($V3=0,"",ROUND(($B3-$C3)/$V3,1))) | G3: =SUMIF(Diário_Avaliações!$B:$B,$A3,Diário_Avaliações!$K:$K)+IFERROR(INDEX(Histórico_Manual!$C:$C,MATCH($A3,Histórico_Manual!$A:$A,0)),0) | H3: =SUMIF(Diário_Avaliações!$B:$B,$A3,Diário_Avaliações!$J:$J)+IFERROR(INDEX(Histórico_Manual!$D:$D,MATCH($A3,Histórico_Manual!$A:$A,0)),0) | I3: =IF(OR(I$1="",I$1="(livre)"),"",IFERROR(SUMIF(Diário_Avaliações!$B:$B,$A3,INDEX(Diário_Avaliações!$L:$S,0,MATCH(I$1,Diário_Avaliações!$L$1:$S$1,0))),0)+IFERROR(INDEX(Histórico_Manual!$G:$K,MATCH($A3,Histórico_Manual!$A:$A,0),MATCH(I$1,Histórico_Manual!$G$1:$K$1,0)),0)) | J3: =IF(OR(J$1="",J$1="(livre)"),"",IFERROR(SUMIF(Diário_Avaliações!$B:$B,$A3,INDEX(Diário_Avaliações!$L:$S,0,MATCH(J$1,Diário_Avaliações!$L$1:$S$1,0))),0)+IFERROR(INDEX(Histórico_Manual!$G:$K,MATCH($A3,Histórico_Manual!$A:$A,0),MATCH(J$1,Histórico_Manual!$G$1:$K$1,0)),0)) | K3: =IF(OR(K$1="",K$1="(livre)"),"",IFERROR(SUMIF(Diário_Avaliações!$B:$B,$A3,INDEX(Diário_Avaliações!$L:$S,0,MATCH(K$1,Diário_Avaliações!$L$1:$S$1,0))),0)+IFERROR(INDEX(Histórico_Manual!$G:$K,MATCH($A3,Histórico_Manual!$A:$A,0),MATCH(K$1,Histórico_Manual!$G$1:$K$1,0)),0)) | L3: =IF(OR(L$1="",L$1="(livre)"),"",IFERROR(SUMIF(Diário_Avaliações!$B:$B,$A3,INDEX(Diário_Avaliações!$L:$S,0,MATCH(L$1,Diário_Avaliações!$L$1:$S$1,0))),0)+IFERROR(INDEX(Histórico_Manual!$G:$K,MATCH($A3,Histórico_Manual!$A:$A,0),MATCH(L$1,Histórico_Manual!$G$1:$K$1,0)),0)) | M3: =IF(OR(M$1="",M$1="(livre)"),"",IFERROR(SUMIF(Diário_Avaliações!$B:$B,$A3,INDEX(Diário_Avaliações!$L:$S,0,MATCH(M$1,Diário_Avaliações!$L$1:$S$1,0))),0)+IFERROR(INDEX(Histórico_Manual!$G:$K,MATCH($A3,Histórico_Manual!$A:$A,0),MATCH(M$1,Histórico_Manual!$G$1:$K$1,0)),0)) | N3: =IF(OR(N$1="",N$1="(livre)"),"",IFERROR(SUMIF(Diário_Avaliações!$B:$B,$A3,INDEX(Diário_Avaliações!$L:$S,0,MATCH(N$1,Diário_Avaliações!$L$1:$S$1,0))),0)+IFERROR(INDEX(Histórico_Manual!$G:$K,MATCH($A3,Histórico_Manual!$A:$A,0),MATCH(N$1,Histórico_Manual!$G$1:$K$1,0)),0)) | O3: =IF(OR(O$1="",O$1="(livre)"),"",IFERROR(SUMIF(Diário_Avaliações!$B:$B,$A3,INDEX(Diário_Avaliações!$L:$S,0,MATCH(O$1,Diário_Avaliações!$L$1:$S$1,0))),0)+IFERROR(INDEX(Histórico_Manual!$G:$K,MATCH($A3,Histórico_Manual!$A:$A,0),MATCH(O$1,Histórico_Manual!$G$1:$K$1,0)),0)) | P3: =IF(OR(P$1="",P$1="(livre)"),"",IFERROR(SUMIF(Diário_Avaliações!$B:$B,$A3,INDEX(Diário_Avaliações!$L:$S,0,MATCH(P$1,Diário_Avaliações!$L$1:$S$1,0))),0)+IFERROR(INDEX(Histórico_Manual!$G:$K,MATCH($A3,Histórico_Manual!$A:$A,0),MATCH(P$1,Histórico_Manual!$G$1:$K$1,0)),0)) | Q3: =SUMIF(Diário_Avaliações!$B:$B,$A3,Diário_Avaliações!$H:$H)+IFERROR(INDEX(Histórico_Manual!$E:$E,MATCH($A3,Histórico_Manual!$A:$A,0)),0) | R3: =SUMIF(Diário_Avaliações!$B:$B,$A3,Diário_Avaliações!$I:$I)+IFERROR(INDEX(Histórico_Manual!$F:$F,MATCH($A3,Histórico_Manual!$A:$A,0)),0) | S3: =IF($C3=0,"—",IF(SUMIF(Diário_Avaliações!$B:$B,$A3,Diário_Avaliações!$D:$D)=0,"Manual",IF(ISNUMBER(MATCH($A3,Histórico_Manual!$A:$A,0)),"Diário + manual","Diário"))) | T3: =IF($C3=0,"",$C3-SUM($I3:$P3)) | U3: 3 | V3: =MAX(0,DATE(2026,3,31)-MAX(TODAY(),DATE(2026,3,1))+1)
A4: Abril | B4: 50 | C4: =SUMIF(Diário_Avaliações!$B:$B,$A4,Diário_Avaliações!$D:$D)+IFERROR(INDEX(Histórico_Manual!$B:$B,MATCH($A4,Histórico_Manual!$A:$A,0)),0) | D4: =IF($B4=0,"",$C4/$B4) | E4: =$C4-$B4 | F4: =IF($C4>=$B4,0,IF($V4=0,"",ROUND(($B4-$C4)/$V4,1))) | G4: =SUMIF(Diário_Avaliações!$B:$B,$A4,Diário_Avaliações!$K:$K)+IFERROR(INDEX(Histórico_Manual!$C:$C,MATCH($A4,Histórico_Manual!$A:$A,0)),0) | H4: =SUMIF(Diário_Avaliações!$B:$B,$A4,Diário_Avaliações!$J:$J)+IFERROR(INDEX(Histórico_Manual!$D:$D,MATCH($A4,Histórico_Manual!$A:$A,0)),0) | I4: =IF(OR(I$1="",I$1="(livre)"),"",IFERROR(SUMIF(Diário_Avaliações!$B:$B,$A4,INDEX(Diário_Avaliações!$L:$S,0,MATCH(I$1,Diário_Avaliações!$L$1:$S$1,0))),0)+IFERROR(INDEX(Histórico_Manual!$G:$K,MATCH($A4,Histórico_Manual!$A:$A,0),MATCH(I$1,Histórico_Manual!$G$1:$K$1,0)),0)) | J4: =IF(OR(J$1="",J$1="(livre)"),"",IFERROR(SUMIF(Diário_Avaliações!$B:$B,$A4,INDEX(Diário_Avaliações!$L:$S,0,MATCH(J$1,Diário_Avaliações!$L$1:$S$1,0))),0)+IFERROR(INDEX(Histórico_Manual!$G:$K,MATCH($A4,Histórico_Manual!$A:$A,0),MATCH(J$1,Histórico_Manual!$G$1:$K$1,0)),0)) | K4: =IF(OR(K$1="",K$1="(livre)"),"",IFERROR(SUMIF(Diário_Avaliações!$B:$B,$A4,INDEX(Diário_Avaliações!$L:$S,0,MATCH(K$1,Diário_Avaliações!$L$1:$S$1,0))),0)+IFERROR(INDEX(Histórico_Manual!$G:$K,MATCH($A4,Histórico_Manual!$A:$A,0),MATCH(K$1,Histórico_Manual!$G$1:$K$1,0)),0)) | L4: =IF(OR(L$1="",L$1="(livre)"),"",IFERROR(SUMIF(Diário_Avaliações!$B:$B,$A4,INDEX(Diário_Avaliações!$L:$S,0,MATCH(L$1,Diário_Avaliações!$L$1:$S$1,0))),0)+IFERROR(INDEX(Histórico_Manual!$G:$K,MATCH($A4,Histórico_Manual!$A:$A,0),MATCH(L$1,Histórico_Manual!$G$1:$K$1,0)),0)) | M4: =IF(OR(M$1="",M$1="(livre)"),"",IFERROR(SUMIF(Diário_Avaliações!$B:$B,$A4,INDEX(Diário_Avaliações!$L:$S,0,MATCH(M$1,Diário_Avaliações!$L$1:$S$1,0))),0)+IFERROR(INDEX(Histórico_Manual!$G:$K,MATCH($A4,Histórico_Manual!$A:$A,0),MATCH(M$1,Histórico_Manual!$G$1:$K$1,0)),0)) | N4: =IF(OR(N$1="",N$1="(livre)"),"",IFERROR(SUMIF(Diário_Avaliações!$B:$B,$A4,INDEX(Diário_Avaliações!$L:$S,0,MATCH(N$1,Diário_Avaliações!$L$1:$S$1,0))),0)+IFERROR(INDEX(Histórico_Manual!$G:$K,MATCH($A4,Histórico_Manual!$A:$A,0),MATCH(N$1,Histórico_Manual!$G$1:$K$1,0)),0)) | O4: =IF(OR(O$1="",O$1="(livre)"),"",IFERROR(SUMIF(Diário_Avaliações!$B:$B,$A4,INDEX(Diário_Avaliações!$L:$S,0,MATCH(O$1,Diário_Avaliações!$L$1:$S$1,0))),0)+IFERROR(INDEX(Histórico_Manual!$G:$K,MATCH($A4,Histórico_Manual!$A:$A,0),MATCH(O$1,Histórico_Manual!$G$1:$K$1,0)),0)) | P4: =IF(OR(P$1="",P$1="(livre)"),"",IFERROR(SUMIF(Diário_Avaliações!$B:$B,$A4,INDEX(Diário_Avaliações!$L:$S,0,MATCH(P$1,Diário_Avaliações!$L$1:$S$1,0))),0)+IFERROR(INDEX(Histórico_Manual!$G:$K,MATCH($A4,Histórico_Manual!$A:$A,0),MATCH(P$1,Histórico_Manual!$G$1:$K$1,0)),0)) | Q4: =SUMIF(Diário_Avaliações!$B:$B,$A4,Diário_Avaliações!$H:$H)+IFERROR(INDEX(Histórico_Manual!$E:$E,MATCH($A4,Histórico_Manual!$A:$A,0)),0) | R4: =SUMIF(Diário_Avaliações!$B:$B,$A4,Diário_Avaliações!$I:$I)+IFERROR(INDEX(Histórico_Manual!$F:$F,MATCH($A4,Histórico_Manual!$A:$A,0)),0) | S4: =IF($C4=0,"—",IF(SUMIF(Diário_Avaliações!$B:$B,$A4,Diário_Avaliações!$D:$D)=0,"Manual",IF(ISNUMBER(MATCH($A4,Histórico_Manual!$A:$A,0)),"Diário + manual","Diário"))) | T4: =IF($C4=0,"",$C4-SUM($I4:$P4)) | U4: 4 | V4: =MAX(0,DATE(2026,4,30)-MAX(TODAY(),DATE(2026,4,1))+1)
A5: Maio | B5: 50 | C5: =SUMIF(Diário_Avaliações!$B:$B,$A5,Diário_Avaliações!$D:$D)+IFERROR(INDEX(Histórico_Manual!$B:$B,MATCH($A5,Histórico_Manual!$A:$A,0)),0) | D5: =IF($B5=0,"",$C5/$B5) | E5: =$C5-$B5 | F5: =IF($C5>=$B5,0,IF($V5=0,"",ROUND(($B5-$C5)/$V5,1))) | G5: =SUMIF(Diário_Avaliações!$B:$B,$A5,Diário_Avaliações!$K:$K)+IFERROR(INDEX(Histórico_Manual!$C:$C,MATCH($A5,Histórico_Manual!$A:$A,0)),0) | H5: =SUMIF(Diário_Avaliações!$B:$B,$A5,Diário_Avaliações!$J:$J)+IFERROR(INDEX(Histórico_Manual!$D:$D,MATCH($A5,Histórico_Manual!$A:$A,0)),0) | I5: =IF(OR(I$1="",I$1="(livre)"),"",IFERROR(SUMIF(Diário_Avaliações!$B:$B,$A5,INDEX(Diário_Avaliações!$L:$S,0,MATCH(I$1,Diário_Avaliações!$L$1:$S$1,0))),0)+IFERROR(INDEX(Histórico_Manual!$G:$K,MATCH($A5,Histórico_Manual!$A:$A,0),MATCH(I$1,Histórico_Manual!$G$1:$K$1,0)),0)) | J5: =IF(OR(J$1="",J$1="(livre)"),"",IFERROR(SUMIF(Diário_Avaliações!$B:$B,$A5,INDEX(Diário_Avaliações!$L:$S,0,MATCH(J$1,Diário_Avaliações!$L$1:$S$1,0))),0)+IFERROR(INDEX(Histórico_Manual!$G:$K,MATCH($A5,Histórico_Manual!$A:$A,0),MATCH(J$1,Histórico_Manual!$G$1:$K$1,0)),0)) | K5: =IF(OR(K$1="",K$1="(livre)"),"",IFERROR(SUMIF(Diário_Avaliações!$B:$B,$A5,INDEX(Diário_Avaliações!$L:$S,0,MATCH(K$1,Diário_Avaliações!$L$1:$S$1,0))),0)+IFERROR(INDEX(Histórico_Manual!$G:$K,MATCH($A5,Histórico_Manual!$A:$A,0),MATCH(K$1,Histórico_Manual!$G$1:$K$1,0)),0)) | L5: =IF(OR(L$1="",L$1="(livre)"),"",IFERROR(SUMIF(Diário_Avaliações!$B:$B,$A5,INDEX(Diário_Avaliações!$L:$S,0,MATCH(L$1,Diário_Avaliações!$L$1:$S$1,0))),0)+IFERROR(INDEX(Histórico_Manual!$G:$K,MATCH($A5,Histórico_Manual!$A:$A,0),MATCH(L$1,Histórico_Manual!$G$1:$K$1,0)),0)) | M5: =IF(OR(M$1="",M$1="(livre)"),"",IFERROR(SUMIF(Diário_Avaliações!$B:$B,$A5,INDEX(Diário_Avaliações!$L:$S,0,MATCH(M$1,Diário_Avaliações!$L$1:$S$1,0))),0)+IFERROR(INDEX(Histórico_Manual!$G:$K,MATCH($A5,Histórico_Manual!$A:$A,0),MATCH(M$1,Histórico_Manual!$G$1:$K$1,0)),0)) | N5: =IF(OR(N$1="",N$1="(livre)"),"",IFERROR(SUMIF(Diário_Avaliações!$B:$B,$A5,INDEX(Diário_Avaliações!$L:$S,0,MATCH(N$1,Diário_Avaliações!$L$1:$S$1,0))),0)+IFERROR(INDEX(Histórico_Manual!$G:$K,MATCH($A5,Histórico_Manual!$A:$A,0),MATCH(N$1,Histórico_Manual!$G$1:$K$1,0)),0)) | O5: =IF(OR(O$1="",O$1="(livre)"),"",IFERROR(SUMIF(Diário_Avaliações!$B:$B,$A5,INDEX(Diário_Avaliações!$L:$S,0,MATCH(O$1,Diário_Avaliações!$L$1:$S$1,0))),0)+IFERROR(INDEX(Histórico_Manual!$G:$K,MATCH($A5,Histórico_Manual!$A:$A,0),MATCH(O$1,Histórico_Manual!$G$1:$K$1,0)),0)) | P5: =IF(OR(P$1="",P$1="(livre)"),"",IFERROR(SUMIF(Diário_Avaliações!$B:$B,$A5,INDEX(Diário_Avaliações!$L:$S,0,MATCH(P$1,Diário_Avaliações!$L$1:$S$1,0))),0)+IFERROR(INDEX(Histórico_Manual!$G:$K,MATCH($A5,Histórico_Manual!$A:$A,0),MATCH(P$1,Histórico_Manual!$G$1:$K$1,0)),0)) | Q5: =SUMIF(Diário_Avaliações!$B:$B,$A5,Diário_Avaliações!$H:$H)+IFERROR(INDEX(Histórico_Manual!$E:$E,MATCH($A5,Histórico_Manual!$A:$A,0)),0) | R5: =SUMIF(Diário_Avaliações!$B:$B,$A5,Diário_Avaliações!$I:$I)+IFERROR(INDEX(Histórico_Manual!$F:$F,MATCH($A5,Histórico_Manual!$A:$A,0)),0) | S5: =IF($C5=0,"—",IF(SUMIF(Diário_Avaliações!$B:$B,$A5,Diário_Avaliações!$D:$D)=0,"Manual",IF(ISNUMBER(MATCH($A5,Histórico_Manual!$A:$A,0)),"Diário + manual","Diário"))) | T5: =IF($C5=0,"",$C5-SUM($I5:$P5)) | U5: 5 | V5: =MAX(0,DATE(2026,5,31)-MAX(TODAY(),DATE(2026,5,1))+1)
A6: Junho | B6: 50 | C6: =SUMIF(Diário_Avaliações!$B:$B,$A6,Diário_Avaliações!$D:$D)+IFERROR(INDEX(Histórico_Manual!$B:$B,MATCH($A6,Histórico_Manual!$A:$A,0)),0) | D6: =IF($B6=0,"",$C6/$B6) | E6: =$C6-$B6 | F6: =IF($C6>=$B6,0,IF($V6=0,"",ROUND(($B6-$C6)/$V6,1))) | G6: =SUMIF(Diário_Avaliações!$B:$B,$A6,Diário_Avaliações!$K:$K)+IFERROR(INDEX(Histórico_Manual!$C:$C,MATCH($A6,Histórico_Manual!$A:$A,0)),0) | H6: =SUMIF(Diário_Avaliações!$B:$B,$A6,Diário_Avaliações!$J:$J)+IFERROR(INDEX(Histórico_Manual!$D:$D,MATCH($A6,Histórico_Manual!$A:$A,0)),0) | I6: =IF(OR(I$1="",I$1="(livre)"),"",IFERROR(SUMIF(Diário_Avaliações!$B:$B,$A6,INDEX(Diário_Avaliações!$L:$S,0,MATCH(I$1,Diário_Avaliações!$L$1:$S$1,0))),0)+IFERROR(INDEX(Histórico_Manual!$G:$K,MATCH($A6,Histórico_Manual!$A:$A,0),MATCH(I$1,Histórico_Manual!$G$1:$K$1,0)),0)) | J6: =IF(OR(J$1="",J$1="(livre)"),"",IFERROR(SUMIF(Diário_Avaliações!$B:$B,$A6,INDEX(Diário_Avaliações!$L:$S,0,MATCH(J$1,Diário_Avaliações!$L$1:$S$1,0))),0)+IFERROR(INDEX(Histórico_Manual!$G:$K,MATCH($A6,Histórico_Manual!$A:$A,0),MATCH(J$1,Histórico_Manual!$G$1:$K$1,0)),0)) | K6: =IF(OR(K$1="",K$1="(livre)"),"",IFERROR(SUMIF(Diário_Avaliações!$B:$B,$A6,INDEX(Diário_Avaliações!$L:$S,0,MATCH(K$1,Diário_Avaliações!$L$1:$S$1,0))),0)+IFERROR(INDEX(Histórico_Manual!$G:$K,MATCH($A6,Histórico_Manual!$A:$A,0),MATCH(K$1,Histórico_Manual!$G$1:$K$1,0)),0)) | L6: =IF(OR(L$1="",L$1="(livre)"),"",IFERROR(SUMIF(Diário_Avaliações!$B:$B,$A6,INDEX(Diário_Avaliações!$L:$S,0,MATCH(L$1,Diário_Avaliações!$L$1:$S$1,0))),0)+IFERROR(INDEX(Histórico_Manual!$G:$K,MATCH($A6,Histórico_Manual!$A:$A,0),MATCH(L$1,Histórico_Manual!$G$1:$K$1,0)),0)) | M6: =IF(OR(M$1="",M$1="(livre)"),"",IFERROR(SUMIF(Diário_Avaliações!$B:$B,$A6,INDEX(Diário_Avaliações!$L:$S,0,MATCH(M$1,Diário_Avaliações!$L$1:$S$1,0))),0)+IFERROR(INDEX(Histórico_Manual!$G:$K,MATCH($A6,Histórico_Manual!$A:$A,0),MATCH(M$1,Histórico_Manual!$G$1:$K$1,0)),0)) | N6: =IF(OR(N$1="",N$1="(livre)"),"",IFERROR(SUMIF(Diário_Avaliações!$B:$B,$A6,INDEX(Diário_Avaliações!$L:$S,0,MATCH(N$1,Diário_Avaliações!$L$1:$S$1,0))),0)+IFERROR(INDEX(Histórico_Manual!$G:$K,MATCH($A6,Histórico_Manual!$A:$A,0),MATCH(N$1,Histórico_Manual!$G$1:$K$1,0)),0)) | O6: =IF(OR(O$1="",O$1="(livre)"),"",IFERROR(SUMIF(Diário_Avaliações!$B:$B,$A6,INDEX(Diário_Avaliações!$L:$S,0,MATCH(O$1,Diário_Avaliações!$L$1:$S$1,0))),0)+IFERROR(INDEX(Histórico_Manual!$G:$K,MATCH($A6,Histórico_Manual!$A:$A,0),MATCH(O$1,Histórico_Manual!$G$1:$K$1,0)),0)) | P6: =IF(OR(P$1="",P$1="(livre)"),"",IFERROR(SUMIF(Diário_Avaliações!$B:$B,$A6,INDEX(Diário_Avaliações!$L:$S,0,MATCH(P$1,Diário_Avaliações!$L$1:$S$1,0))),0)+IFERROR(INDEX(Histórico_Manual!$G:$K,MATCH($A6,Histórico_Manual!$A:$A,0),MATCH(P$1,Histórico_Manual!$G$1:$K$1,0)),0)) | Q6: =SUMIF(Diário_Avaliações!$B:$B,$A6,Diário_Avaliações!$H:$H)+IFERROR(INDEX(Histórico_Manual!$E:$E,MATCH($A6,Histórico_Manual!$A:$A,0)),0) | R6: =SUMIF(Diário_Avaliações!$B:$B,$A6,Diário_Avaliações!$I:$I)+IFERROR(INDEX(Histórico_Manual!$F:$F,MATCH($A6,Histórico_Manual!$A:$A,0)),0) | S6: =IF($C6=0,"—",IF(SUMIF(Diário_Avaliações!$B:$B,$A6,Diário_Avaliações!$D:$D)=0,"Manual",IF(ISNUMBER(MATCH($A6,Histórico_Manual!$A:$A,0)),"Diário + manual","Diário"))) | T6: =IF($C6=0,"",$C6-SUM($I6:$P6)) | U6: 6 | V6: =MAX(0,DATE(2026,6,30)-MAX(TODAY(),DATE(2026,6,1))+1)
A7: Julho | B7: 50 | C7: =SUMIF(Diário_Avaliações!$B:$B,$A7,Diário_Avaliações!$D:$D)+IFERROR(INDEX(Histórico_Manual!$B:$B,MATCH($A7,Histórico_Manual!$A:$A,0)),0) | D7: =IF($B7=0,"",$C7/$B7) | E7: =$C7-$B7 | F7: =IF($C7>=$B7,0,IF($V7=0,"",ROUND(($B7-$C7)/$V7,1))) | G7: =SUMIF(Diário_Avaliações!$B:$B,$A7,Diário_Avaliações!$K:$K)+IFERROR(INDEX(Histórico_Manual!$C:$C,MATCH($A7,Histórico_Manual!$A:$A,0)),0) | H7: =SUMIF(Diário_Avaliações!$B:$B,$A7,Diário_Avaliações!$J:$J)+IFERROR(INDEX(Histórico_Manual!$D:$D,MATCH($A7,Histórico_Manual!$A:$A,0)),0) | I7: =IF(OR(I$1="",I$1="(livre)"),"",IFERROR(SUMIF(Diário_Avaliações!$B:$B,$A7,INDEX(Diário_Avaliações!$L:$S,0,MATCH(I$1,Diário_Avaliações!$L$1:$S$1,0))),0)+IFERROR(INDEX(Histórico_Manual!$G:$K,MATCH($A7,Histórico_Manual!$A:$A,0),MATCH(I$1,Histórico_Manual!$G$1:$K$1,0)),0)) | J7: =IF(OR(J$1="",J$1="(livre)"),"",IFERROR(SUMIF(Diário_Avaliações!$B:$B,$A7,INDEX(Diário_Avaliações!$L:$S,0,MATCH(J$1,Diário_Avaliações!$L$1:$S$1,0))),0)+IFERROR(INDEX(Histórico_Manual!$G:$K,MATCH($A7,Histórico_Manual!$A:$A,0),MATCH(J$1,Histórico_Manual!$G$1:$K$1,0)),0)) | K7: =IF(OR(K$1="",K$1="(livre)"),"",IFERROR(SUMIF(Diário_Avaliações!$B:$B,$A7,INDEX(Diário_Avaliações!$L:$S,0,MATCH(K$1,Diário_Avaliações!$L$1:$S$1,0))),0)+IFERROR(INDEX(Histórico_Manual!$G:$K,MATCH($A7,Histórico_Manual!$A:$A,0),MATCH(K$1,Histórico_Manual!$G$1:$K$1,0)),0)) | L7: =IF(OR(L$1="",L$1="(livre)"),"",IFERROR(SUMIF(Diário_Avaliações!$B:$B,$A7,INDEX(Diário_Avaliações!$L:$S,0,MATCH(L$1,Diário_Avaliações!$L$1:$S$1,0))),0)+IFERROR(INDEX(Histórico_Manual!$G:$K,MATCH($A7,Histórico_Manual!$A:$A,0),MATCH(L$1,Histórico_Manual!$G$1:$K$1,0)),0)) | M7: =IF(OR(M$1="",M$1="(livre)"),"",IFERROR(SUMIF(Diário_Avaliações!$B:$B,$A7,INDEX(Diário_Avaliações!$L:$S,0,MATCH(M$1,Diário_Avaliações!$L$1:$S$1,0))),0)+IFERROR(INDEX(Histórico_Manual!$G:$K,MATCH($A7,Histórico_Manual!$A:$A,0),MATCH(M$1,Histórico_Manual!$G$1:$K$1,0)),0)) | N7: =IF(OR(N$1="",N$1="(livre)"),"",IFERROR(SUMIF(Diário_Avaliações!$B:$B,$A7,INDEX(Diário_Avaliações!$L:$S,0,MATCH(N$1,Diário_Avaliações!$L$1:$S$1,0))),0)+IFERROR(INDEX(Histórico_Manual!$G:$K,MATCH($A7,Histórico_Manual!$A:$A,0),MATCH(N$1,Histórico_Manual!$G$1:$K$1,0)),0)) | O7: =IF(OR(O$1="",O$1="(livre)"),"",IFERROR(SUMIF(Diário_Avaliações!$B:$B,$A7,INDEX(Diário_Avaliações!$L:$S,0,MATCH(O$1,Diário_Avaliações!$L$1:$S$1,0))),0)+IFERROR(INDEX(Histórico_Manual!$G:$K,MATCH($A7,Histórico_Manual!$A:$A,0),MATCH(O$1,Histórico_Manual!$G$1:$K$1,0)),0)) | P7: =IF(OR(P$1="",P$1="(livre)"),"",IFERROR(SUMIF(Diário_Avaliações!$B:$B,$A7,INDEX(Diário_Avaliações!$L:$S,0,MATCH(P$1,Diário_Avaliações!$L$1:$S$1,0))),0)+IFERROR(INDEX(Histórico_Manual!$G:$K,MATCH($A7,Histórico_Manual!$A:$A,0),MATCH(P$1,Histórico_Manual!$G$1:$K$1,0)),0)) | Q7: =SUMIF(Diário_Avaliações!$B:$B,$A7,Diário_Avaliações!$H:$H)+IFERROR(INDEX(Histórico_Manual!$E:$E,MATCH($A7,Histórico_Manual!$A:$A,0)),0) | R7: =SUMIF(Diário_Avaliações!$B:$B,$A7,Diário_Avaliações!$I:$I)+IFERROR(INDEX(Histórico_Manual!$F:$F,MATCH($A7,Histórico_Manual!$A:$A,0)),0) | S7: =IF($C7=0,"—",IF(SUMIF(Diário_Avaliações!$B:$B,$A7,Diário_Avaliações!$D:$D)=0,"Manual",IF(ISNUMBER(MATCH($A7,Histórico_Manual!$A:$A,0)),"Diário + manual","Diário"))) | T7: =IF($C7=0,"",$C7-SUM($I7:$P7)) | U7: 7 | V7: =MAX(0,DATE(2026,7,31)-MAX(TODAY(),DATE(2026,7,1))+1)
